Workbook

Sheet PDF COMPLEXO
B5: ORÇAMENTO (VÁLIDO POR 10 DIAS)
B7: CLIENTE: | C7: =ENTRADA!C9 -> 0
B8: ENDEREÇO: | C8: =ENTRADA!C10& " - "&ENTRADA!D10 -> PORTO UNIÃO - SC
B10: GALPÃO PRÉ-MOLDADO
B11: MEDIDA DE | C11: =ENTRADA!D2 -> 9x60
B12: ÁREA DE | C12: =ENTRADA!D3&" m²" -> 540 m²
B13: PÉ DIREITO | C13: =PILARES!D12&" metros" -> 5 metros
B15: Inclui: Cobertura
B16: 2 eitão fechado em aluzinco Tp40
B17: =COBERTURA!C24& " tesouras metálicas:" -> 13 tesouras metálicas:
B18: perfil de | C18: =COBERTURA!C17 &" e " & COBERTURA!C20 -> PERFIL U 75mm 2,00 e PERFIL U 68mm 2,00
B19: =COBERTURA!C30 &" m² de cobertura: " -> 622,1 m² de cobertura:
B20: =COBERTURA!B28 -> TELHA SIMPLES
B21: terças metálicas enrrigecidas perfil 75mm/2mm em pintura sintética
B22: contraventamento em barra redonda
B24: Inclui:
B25: 26 pilares de 6m
B35: VALOR TOTAL DE: | D35: =164000 -> 164000
B38: Não inclui:
B39: • Sem piso, sem calha, sem fechamento e sem esquadrias
B40: • Agregados e cimento para fundação por conta do contratante
B41: se a fundação exceder 5 metros fica a custo do cliente
B43: • PAGAMENTO:
B44: • 50% DE ENTRADA NA ASSINATURA DO CONTRATO;
B45: • 25% NO INICIO DA OBRA;
B46: • 25% NA CONCLUSÃO DA OBRA;
B48: • PRAZO:
B49: 90 dias úteis após a assinatura do contrato;
B50: Em caso de projeto, 90 dias após a entrega do projeto;

Sheet PDF SIMPLES
B5: ORÇAMENTO (VÁLIDO POR 10 DIAS)
B7: CLIENTE: | C7: =ENTRADA!C9 -> 0
B8: ENDEREÇO: | C8: Canoinhas - SC
B10: GALPÃO PRÉ-MOLDADO
B11: MEDIDA DE | C11: =ENTRADA!D2 -> 9x60
B12: ÁREA DE | C12: =ENTRADA!D3&" m²" -> 540 m²
B13: PÉ DIREITO | C13: =PILARES!D12&" metros" -> 5 metros
B15: Inclui:
B16: =PILARES!C11&" pilares" -> 26 pilares
B17: 2 eitão fechado em aluzinco Tp40
B18: =COBERTURA!C24&" tesouras metálicas com: "&COBERTURA!C17&" e " &COBERTURA!C20 -> 13 tesouras metálicas com: PERFIL U 75mm 2,00 e PERFIL U 68mm 2,00
B19: =COBERTURA!C30 &" m² de cobertura em: "&COBERTURA!B28 -> 622,1 m² de cobertura em: TELHA SIMPLES
B20: terças metálicas enrrigecidas perfil 75mm/2mm em pintura sintética
B21: contraventamento em barra redonda
B22: =VIGAS!C12&" m de viga pré-moldada " -> 50 m de viga pré-moldada
B23: =LAJE!B3&" m² de laje pré-moldada medida de 6x8" -> 10 m² de laje pré-moldada medida de 6x8
B24: ART de fabricação e montagem, frete incluso
B26: VALOR TOTAL DE: | D26: 31000
B29: Não inclui:
B30: • Sem piso, sem calha, sem fechamento e sem esquadrias
B31: • Agregados e cimento para fundação por conta do contratante
B32: se a fundação exceder 5 metros fica a custo do cliente
B34: • PAGAMENTO:
B35: • 50% DE ENTRADA NA ASSINATURA DO CONTRATO;
B36: • 25% NO INICIO DA OBRA;
B37: • 25% NA CONCLUSÃO DA OBRA;
B39: • PRAZO:
B40: 90 dias úteis após a assinatura do contrato;
B41: Em caso de projeto, 90 dias após a entrega do projeto;

Sheet BANCO DE DADOS
B2: BANCO DE DADOS
B4: MATERIAL | C4: DIMENSÃO | D4: VALOR UNITÁRIO | E4: MEDIDA DE COMPRA DE BARRA(m) | F4: VALOR POR m | I4: FERRO ø | J4: VALOR UNITÁRIO | K4: MEDIDA DE COMPRA DA BARRA(m) | L4: VALOR DE 6m | M4: VALOR POR m | Q4: CONCRETO | R4: VALOR UNITÁRIO | S4: MEDIDA DE COMPRA kg/L | T4: VALOR POR kg / L | U4: QNTD KG TRAÇO | V4: VALOR TOTAL | Y4: CIDADE | Z4: ESTADO | AA4: DISTÂNCIA (KM)
B5: TELHA ISOPOR E MANTA | D5: 75 | E5: 1 | F5: =(D5/E5) -> 75 | I5: 5 | J5: 15.9 | K5: 12 | L5: =J5/2 -> 7.95 | M5: =J5/K5 -> 1.325 | Q5: CIMENTO | R5: 34 | S5: 40 | T5: =R5/S5 -> 0.85 | U5: 320 | V5: =U5*T5 -> 272 | Y5: PORTO UNIÃO | Z5: SC | AA5: 40
B6: TELHA BANDEJA | D6: 105.8 | E6: 1 | F6: =(D6/E6) -> 105.8 | I6: 6.3 | J6: 26.7 | K6: 12 | L6: =J6/2 -> 13.35 | M6: =J6/K6 -> 2.225 | Q6: AREIA | R6: 64 | S6: 1000 | T6: =R6/S6 -> 0.064 | U6: 655 | V6: =U6*T6 -> 41.92 | Y6: UNIÃO DA VITÓRIA | Z6: PR | AA6: 42
B7: TELHA SANDUICHE | D7: 86.8 | E7: 1 | F7: =D7*E7 -> 86.8 | I7: 8 | J7: 40.61 | K7: 12 | L7: =J7/2 -> 20.305 | M7: =J7/K7 -> 3.3841667 | Q7: BRITA/PÓ | R7: 75 | S7: 1000 | T7: =R7/S7 -> 0.075 | U7: 300 | V7: =U7*T7 -> 22.5 | Y7: CANOINHAS | Z7: SC | AA7: 46
B8: TELHA SIMPLES TP 25 Pintada | D8: 48.9 | E8: 1 | F8: =D8*E8 -> 48.9 | I8: 10 | J8: 61.76 | K8: 12 | L8: =J8/2 -> 30.88 | M8: =J8/K8 -> 5.1466667 | Q8: PÓ | R8: 75 | S8: 1000 | T8: =R8/S8 -> 0.075 | U8: 925 | V8: =U8*T8 -> 69.375 | Y8: TRÊS BARRAS | Z8: SC | AA8: 65
B9: TELHA SIMPLES | D9: 36.9 | E9: 1 | F9: =D9/E9 -> 36.9 | I9: 12.5 | J9: 94.07 | K9: 12 | L9: =J9/2 -> 47.035 | M9: =J9/K9 -> 7.8391667 | Q9: ADITIVO 730 CAA SUPERPLASTIFICANTE | R9: 2111 | S9: 200 | T9: =R9/S9 -> 10.555 | U9: 1.2 | V9: =U9*T9 -> 12.666 | Y9: SÃO MATEUS DO SUL | Z9: PR | AA9: 72
B10: TELHA COM ISOPOR | D10: 51.9 | E10: 1 | F10: =D10/E10 -> 51.9 | I10: 16 | J10: 162.13 | K10: 12 | L10: =J10/2 -> 81.065 | M10: =J10/K10 -> 13.510833 | Q10: ACELERADOR (SECANTE) | R10: 1400 | S10: 200 | T10: =R10/S10 -> 7 | U10: 1 | V10: =U10*T10 -> 7 | Y10: BELA VISTA DO TOLDO | Z10: SC | AA10: 41
B11: TELHA+MANTA | D11: 46.9 | E11: 1 | F11: =D11/E11 -> 46.9 | I11: 20 | J11: 259.59 | K11: 12 | L11: =J11/2 -> 129.795 | M11: =J11/K11 -> 21.6325 | Q11: DESMOLDANTE | R11: 2180 | S11: 200 | T11: =R11/S11 -> 10.9 | U11: 0.05 | V11: =U11*T11 -> 0.545 | Y11: PAULA FREITAS | Z11: PR | AA11: 5
B12: TELHA+EPS+PINTADA | D12: 69 | E12: 1 | F12: =D12/E12 -> 69 | I12: TELA 4,2 | J12: 1686 | K12: 120 | L12: =J12/2 -> 843 | M12: =J12/K12 -> 14.05 | Q12: ÁGUA | U12: 175 | Y12: PAULA FRONTIN | Z12: PR | AA12: 32
B13: CHAPA FRIZADA | D13: 89.9 | E13: 1 | F13: =D13/E13 -> 89.9 | Q13: TOTAL POR M³ | T13: kg | U13: =SUM(U5:U12) -> 2377.25 | V13: =SUM(V5:V11) -> 426.006 | Y13: RIO AZUL | Z13: PR | AA13: 74
B14: PERFIL U 75mm 2,00 | C14: 75X2 | D14: 106.2 | E14: 6 | F14: =D14/E14 -> 17.7 | I14: CHAPA | J14: 27 | K14: 1 | M14: =J14 -> 27 | Y14: MALLET | Z14: PR | AA14: 53
B15: PERFIL U 75,mm 2,25 | C15: 75X2,25 | D15: 117.8 | E15: 6 | F15: =D15/E15 -> 19.633333 | Y15: CRUZ MACHADO | Z15: PR | AA15: 93
B16: PERFIL U 75 mm 2,65 | C16: 75X2,65 | D16: 136.8 | E16: 6 | F16: =D16/E16 -> 22.8 | I16: ESPAÇADORES | J16: 140 | K16: 500 | M16: =J16/K16 -> 0.28 | Y16: PAPANDUVA | Z16: SC | AA16: 90
B17: PERFIL U 75 mm 3 | C17: 75X3 | D17: 155.8 | E17: 6 | F17: =D17/E17 -> 25.966667 | Y17: MATOS COSTA | Z17: SC | AA17: 67
B18: PERFIL U 68mm 2,00 | C18: 68X2 | D18: 85.9 | E18: 6 | F18: =D18/E18 -> 14.316667 | Y18: TIMBÓ GRANDE | Z18: SC | AA18: 61
B19: PERFIL U 68mm 2,25 | C19: 68X2,25 | D19: 97.3 | E19: 6 | F19: =D19/E19 -> 16.216667 | I19: PAREDE METÁLICA | J19: R$120,00m² | Y19: MAFRA | Z19: SC | AA19: 112
B20: PERFIL U 68mm 3 | C20: 68X23 | D20: 114.5 | E20: 6 | F20: =D20/E20 -> 19.083333 | Y20: CALMON | Z20: SC | AA20: 85
B21: PERFIL U 92 mm 2,00 | C21: 92X2 | D21: 103.36 | E21: 6 | F21: =D21/E21 -> 17.226667 | Y21: MAJOR VIEIRA | Z21: SC | AA21: 70
B22: PERFIL U 92 mm 2,25 | C22: 92X2,25 | D22: 115.5 | E22: 6 | F22: =D22/E22 -> 19.25 | Y22: SANTA CECÍLIA | Z22: SC | AA22: 126
B23: PERFIL U 92 mm 3 | C23: 92X3 | D23: 148.5 | E23: 6 | F23: =D23/E23 -> 24.75 | Y23: BITURUNA | Z23: PR | AA23: 117
B24: PERFIL U 100mm 2,00 | C24: 100X2 | D24: 123.12 | E24: 6 | F24: =D24/E24 -> 20.52
B25: PERFIL U 100mm2,25 | C25: 100X2,25 | D25: 139.08 | E25: 6 | F25: =D25/E25 -> 23.18
B26: PERFIL U 100mm2,65 | C26: 100X2,65 | D26: 162.33 | E26: 6 | F26: =D26/E26 -> 27.055
B27: PERFIL U 100mm 3 | C27: 100X3 | D27: 182.85 | E27: 6 | F27: =D27/E27 -> 30.475
B28: TERÇA ENR 75mm 2,00 | C28: 2 | D28: 123.12 | E28: 6 | F28: =D28/E28 -> 20.52
B29: TERÇA ENR 75mm 2,25 | C29: 2.25 | D29: 137.56 | E29: 6 | F29: =D29/E29 -> 22.926667
B30: TERÇA ENR 75mm 2,65 | C30: 2.65 | D30: 162.64 | E30: 6 | F30: =D30/E30 -> 27.106667
B31: BARRA RED 1/4 VERGA | D31: 22.8 | E31: 12 | F31: =D31/E31 -> 1.9
B32: BARRA RED 5/16 VERGA | D32: 35 | E32: 12 | F32: =D32/E32 -> 2.9166667
B33: TIRANTE | E33: 6 | F33: =D33/E33 -> 0
B34: CUMEEIRA | D34: 37.51 | E34: 1 | F34: =D34/E34 -> 37.51
B35: perfis para tesouras
D36: (mm)
B37: vão (m) | C37: 13 | D37: 2
B38: perfil (mm) | C38: 75
B39: interno (mm) | C39: 68
B40: vão (m) | C40: 14 | D40: 2.65
B41: perfil (mm) | C41: 75
B42: interno (mm) | C42: 68
...

Sheet ENTRADA
C2: MEDIDA | D2: =D4&"x"&D5 -> 9x60
C3: ÁREA | D3: =D4*D5 -> 540
C4: FRENTE | D4: 9
C5: LATERAL | D5: 60
C6: ALTURA LIVRE | D6: 5
C7: FRENTE | D7: =D4 -> 9
C8: LADO | D8: =D5 -> 60
B9: CLIENTE
B10: ENDEREÇO | C10: PORTO UNIÃO | D10: =VLOOKUP(C10,B64:C83,2,0) -> SC
B11: FECHAMENTO | C11: NÃO
B12: PORTA | C12: NÃO
B13: JANELA | C13: NÃO
B14: PLACAS | C14: NÃO
B15: TELHA | C15: TELHA SIMPLES
B16: COBERTURA | C16: DUAS ÁGUAS
B17: PLATIBANDA | C17: NÃO
B18: PROJETO | C18: SIM
B19: LAJE | C19: NÃO
B20: VIGA | C20: NÃO
B21: PORTA | C21: NÃO
B26: TESOURA | C26: =COBERTURA!C25 -> 11105.9 | D26: =C26*2 -> 22211.8
B27: TELHA | C27: =COBERTURA!C31 -> 22955.49 | D27: =C27+(C27*0.3) -> 29842.137
B28: TERÇA | C28: =COBERTURA!C40 -> 11265.48 | D28: =C28*2 -> 22530.96
B29: EITÃO | C29: =COBERTURA!C47 -> 800 | D29: =C29*2 -> 1600
B30: CUMEEIRA | C30: =COBERTURA!C52 -> 2288.11 | D30: =C30*2 -> 4576.22
B31: PLATIBANDA | C31: =IF(C17=C57,FECHAMENTOS!C9,0) -> 0 | D31: =C31*2 -> 0
B32: PILAR | C32: =PILARES!C22 -> 14135.853 | D32: =C32*2 -> 28271.705
B33: CÁLICE | C33: =CÁLICES!C11 -> 5200 | D33: =C33*2 -> 10400
B35: LAJE | C35: =IF(C19=C57,LAJE!B5,0) -> 0 | D35: =C35*2 -> 0
B36: VIGA | C36: =IF(C20=C57,VIGAS!C22,0) -> 0 | D36: =C36*2 -> 0
B37: PLACA | C37: =IF(C14=C57,FECHAMENTOS!G18,0) -> 0 | D37: =C37*2 -> 0
B38: FRETE | C38: =C54 -> 960 | D38: =C38*2 -> 1920
B41: TOTAL CUSTO | C41: =SUM(C26:C38) -> 68710.833 | D41: -
B42: PROJETO | C42: =IF(C18=C57,C61,0) -> 8100 | D42: =C42*1 -> 8100
B43: PORTA | C43: =IF(C21=C57,PORTÃO!C11,0) -> 0 | D43: =C43*1 -> 0
B44: DOBRANDO | C44: =C41*2+C42+C43 -> 145521.67 | D44: =SUM(D26:D42) -> 129452.82
B45: COM NOTA | C45: =(C44*0.125)+C44 -> 163711.87 | D45: =(D44*0.08)+D44 -> 139809.05
B46: VALOR POR m² | C46: =C45/D3 -> 303.17014 | D46: =D45/D3 -> 258.90564
B48: VALOR SÓ COBERTURA | C48: =D26+D27+D28+D29+D30 -> 80761.117
B50: FRETE
...

Sheet COBERTURA
B3: COBERTURA
B4: FRENTE | D4: LADO
B5: =ENTRADA!D4+1 -> 10 | D5: =ENTRADA!D5+1 -> 61
B8: COBERTURA
B9: Altura | C9: =B5/10 -> 1
B10: Lado | C10: =B5/2 -> 5
B11: Medida inclinação | C11: =SQRT((C9^2)+(C10^2)) -> 5.0990195
B13: TESOURA
B14: Perímetro | C14: =(B5+C11+C11) -> 20.198039
B15: Qntd perfil | C15: =C14/6 -> 3.3663398
B16: Qntd perfil externo | C16: =CEILING(C15,1) -> 4
B17: Qual perfil | C17: PERFIL U 75mm 2,00
B18: Valor perfil externo | C18: =VLOOKUP(C17,'BANCO DE DADOS'!B5:F34,3,0) -> 106.2
B19: Qntd perfil interno | C19: =C16+1 -> 5
B20: Qual perfil | C20: PERFIL U 68mm 2,00
B21: Valor perfil interno | C21: =VLOOKUP(C20,'BANCO DE DADOS'!B10:D22,3,0) -> 85.9
B23: Custo por tesoura | C23: =(C16*C18)+(C19*C21) -> 854.3
B24: Qntd de tesoura | C24: =ROUNDDOWN((D5/5)+1,0) -> 13
B25: Valor total | C25: =C23*C24 -> 11105.9
B26: TELHA
B27: Modelo de telha | C27: valor
B28: =ENTRADA!C15 -> TELHA SIMPLES | C28: =VLOOKUP(B28,'BANCO DE DADOS'!B5:D9,3,0) -> 36.9
B30: Metragem | C30: =ROUNDUP((C11*D5)*2,1) -> 622.1
B31: Valor | C31: =C28*C30 -> 22955.49
B33: TERÇA
B34: Valor por metro | C34: ='BANCO DE DADOS'!F28 -> 20.52
B35: Metragem | C35: =D5 -> 61
B36: Qntd 1 lado | C36: =C11/1.2 -> 4.2491829
B37: Qntd total | C37: =ROUNDUP((C36*2),0) -> 9
B38: Total de metros | C38: =C35*C37 -> 549
B39: Qntd de terça | C39: =C38/6 -> 91.5
B40: Valor | C40: =C38*C34 -> 11265.48
B42: EITÃO
B43: Área | C43: =C9*C10 -> 5
B44: Valor por m2 | C44: 80
B45: Custo | C45: =C43*C44 -> 400
B46: Qntd de eitão | C46: 2
B47: Total | C47: =C45*C46 -> 800
B49: CUMEEIRA
B50: Metragem | C50: =D5 -> 61
...

Sheet PILARES
B2: PILARES
B5: DIMENSÃO | C5: ÁREA | E5: CONCRETO | L5: AÇO LONGITUDINAL | W5: AÇO ESTRIBO | AF5: GANCHO
B6: 26X30 | C6: =0.26*0.3 -> 0.078 | E6: Área base | F6: Comprimento | G6: Volume | H6: Por pilar | I6: Número de pilar | J6: Custo | L6: Número de barras | M6: Comprimento | N6: Comprimento total | O6: ø da barra | P6: Medida da barra de compra | Q6: Valor por barra | R6: Valor pra compra da barra | S6: Custo por pilar | T6: Número de pilar | U6: Custo | W6: Comprimento do pilar | X6: Número de estribos | Y6: Comprimento do estribo | Z6: Comprimento total de barra | AA6: Ferro ø5/m | AB6: Valor por pilar | AC6: Número de pilar | AD6: Custo total | AF6: Número de ganchos | AG6: Ferro | AH6: Valor por metro | AI6: Medida do gancho (m) | AJ6: Quantidade em metro | AK6: Valor total
B7: 25X40 | C7: =0.25*0.4 -> 0.1 | E7: =$C$10 -> 0.078 | F7: =C12 -> 6 | G7: =F7*E7 -> 0.468 | H7: =G7*'BANCO DE DADOS'!$V$13 -> 199.37081 | I7: =C11 -> 26 | J7: =I7*H7 -> 5183.641 | L7: 2 | M7: =C12 -> 6 | N7: =M7*L7 -> 12 | O7: 10 | P7: =IF(M7<=6,6,12) -> 6 | Q7: =VLOOKUP(O7,'BANCO DE DADOS'!$I$5:$J$14,2,'BANCO DE DADOS'!$J$5:$J$14) -> 61.76 | R7: =IF(P7>6,Q7,(Q7/2)) -> 30.88 | S7: =R7*L7 -> 61.76 | T7: =C11 -> 26 | U7: =T7*S7 -> 1605.76 | W7: =C12 -> 6 | X7: =(W7/0.15)+1 -> 41 | Y7: 1.3 | Z7: =Y7*X7 -> 53.3 | AA7: ='BANCO DE DADOS'!$M$5 -> 1.325 | AB7: =AA7*Z7 -> 70.6225 | AC7: =C11 -> 26 | AD7: =AC7*AB7 -> 1836.185 | AF7: =C11*2 -> 52 | AG7: 10 | AH7: =VLOOKUP(AG7,'BANCO DE DADOS'!I5:M14,5,'BANCO DE DADOS'!M5:M14) -> 5.1466667 | AI7: 1 | AJ7: =AF7*AI7 -> 52 | AK7: =AJ7*AH7 -> 267.62667
B8: 17X27 | C8: =0.17*0.27 -> 0.0459 | L8: 4 | M8: =C12 -> 6 | N8: =M8*L8 -> 24 | O8: 12.5 | P8: =IF(M8<=6,6,12) -> 6 | Q8: =VLOOKUP(O8,'BANCO DE DADOS'!$I$5:$J$14,2,'BANCO DE DADOS'!$J$5:$J$14) -> 94.07 | R8: =IF(P8>6,Q8,(Q8/2)) -> 47.035 | S8: =R8*L8 -> 188.14 | T8: =C11 -> 26 | U8: =T8*S8 -> 4891.64
B10: Qual usado | C10: =C6 -> 0.078
B11: Número de pilar | C11: 26 | D11: Terreo | E11: Fundação | F11: Laje | G11: 1° Pav | H11: Platibanda
B12: Altura | C12: =D12+E12+F12+G12+H12 -> 6 | D12: =ENTRADA!D6 -> 5 | E12: 1 | F12: 0
B13: Metragem total | C13: =C11*C12 -> 156
B14: CUSTO TOTAL
B15: Concreto | C15: =SUM(J7:J9) -> 5183.641
B16: Aço longitudinal | C16: =SUM(U7:U8) -> 6497.4
B17: Estribo | C17: =SUM(AD7:AD7) -> 1836.185
B18: Chapa | C18: =C11*('BANCO DE DADOS'!J14/2) -> 351
B19: Gancho | C19: =AK7 -> 267.62667
B20: Mão de obra
B21: Consolo
B22: TOTAL | C22: =SUM(C15:C20) -> 14135.853
B23: Por pilar | C23: =C22/C11 -> 543.68664
B24: Por metro | C24: =C22/C13 -> 90.61444

Sheet CÁLICES
C3: Unidade | D3: Comprimento | E3: Metragem | F3: Custo
B4: Concreto | C4: =(((0.08*1)*0.63)+(0.08*1*0.7))*2 -> 0.2128 | F4: =C4*'BANCO DE DADOS'!V13 -> 90.654077
B6: Ferro | C6: 4 | D6: 1 | E6: =C6*D6 -> 4 | F6: =E6*'BANCO DE DADOS'!M7 -> 13.536667
B7: Estribos | C7: 8 | D7: =0.7+0.6+0.7+0.6 -> 2.6 | E7: =C7*D7 -> 20.8 | F7: =E7*'BANCO DE DADOS'!M7 -> 70.390667
B8: Malha | C8: =0.7+0.6+0.7+0.6 -> 2.6 | F8: =C8*'BANCO DE DADOS'!M12 -> 36.53
C9: 200 | F9: =F4+F6+F7+F8 -> 211.11141
B10: Número de pilares | C10: =PILARES!C11 -> 26
B11: Custo | C11: =C9*C10 -> 5200

Sheet FECHAMENTOS
B2: PLATIBANDA | F2: PLACA
B3: PerÍmetro | C3: =ENTRADA!D4+ENTRADA!D5+ENTRADA!D4+ENTRADA!D5 -> 138 | D3: m
B4: Altura | C4: 1 | D4: m | G4: Valor | H4: Metragem usada | I4: Total
B5: Total em metros | C5: =C3*C4 -> 138 | D5: m² | F5: Concreto | G5: ='BANCO DE DADOS'!V13 -> 426.006 | H5: =1*5*0.08 -> 0.4 | I5: =G5*H5 -> 170.4024
B6: Custo por m de zinco | C6: =120/2 -> 60 | F6: Malha | G6: ='BANCO DE DADOS'!M12 -> 14.05 | H6: 5 | I6: =G6*H6 -> 70.25
B7: Para eitão | C7: =160/2 -> 80 | F7: Gancho | G7: ='BANCO DE DADOS'!M7 -> 3.3841667 | H7: 2 | I7: =G7*H7 -> 6.7683333
B8: Total | C8: =C6*C5 -> 8280 | F8: Barras 8mm | G8: =G7 -> 3.3841667 | H8: =5*3 -> 15 | I8: =G8*H8 -> 50.7625
B9: Dobrando | C9: =C8*2 -> 16560 | F9: Espaçadores | G9: ='BANCO DE DADOS'!M15 -> 0 | H9: 20 | I9: =G9*H9 -> 0
F10: Valor total de 5 metros | I10: =SUM(I5:I9) -> 298.18323 | J10: placa
F11: Valor por metro | G11: 60 | I11: =I10/5 -> 59.636647 | J11: metro
H12: Qntd de vãos | I12: Total | J12: Q por vão
B13: TERÇA | F13: P.U | G13: 11 | H13: 24 | I13: =J13*H13*G13 -> 5280 | J13: 20
B14: Valor por metro | C14: ='BANCO DE DADOS'!F23 -> 24.75 | F14: area das placas
B15: Metragem | C15: 101 | F15: Perímetro | G15: =C3 -> 138 | H15: m
B16: Qntd horizontal | C16: 4 | F16: Altura | G16: 5.5 | H16: m
B17: Metragem hor | C17: =C15*C16 -> 404 | F17: Área das plcas | G17: 345 | H17: m²
B18: Qntd vertical | C18: 18 | F18: Valor custo | G18: =G17*G11+I13 -> 25980
B19: Metragem vertical | C19: 4
C20: =C19*C18 -> 72 | F20: Dobrando | G20: =G18*2 -> 51960
B21: Total de metros | C21: =C17+C20 -> 476
B22: Valor | C22: =C21*C14 -> 11781
F24: ÁREA DAS PLACAS EXTRAS
F25: PerÍmetro | G25: 32 | H25: m
F26: Altura | G26: 3 | H26: m
F27: Área das plcas | G27: =G25*G26 -> 96 | H27: m²
F28: Valor custo | G28: =G27*G11 -> 5760

Sheet VIGAS
B2: VIGAS
B5: DIMENSÃO | C5: ÁREA | E5: CONCRETO | L5: AÇO LONGITUDINAL | W5: AÇO ESTRIBO | AF5: GANCHO
B6: 50X22 | C6: =0.5*0.22 -> 0.11 | E6: Área base | F6: Comprimento | G6: Volume | H6: Por viga | I6: Número de vigas | J6: Custo | L6: Número de barras | M6: Comprimento | N6: Comprimento total | O6: ø da barra | P6: Medida da barra de compra | Q6: Valor por barra | R6: Valor pra compra da barra | S6: Custo por viga | T6: Número de vigas | U6: Custo | W6: Comprimento da viga | X6: Número de estribos | Y6: Comprimento do estribo | Z6: Comprimento total de barra | AA6: Ferro ø5/m | AB6: Custo por viga | AC6: Número de vigas | AD6: Custo total | AF6: Número de ganchos | AG6: Ferro | AH6: Valor por metro | AI6: Medida do gancho (m) | AJ6: Quantidade em metro | AK6: Valor total
B7: 60X22 | C7: =0.6*0.22 -> 0.132 | E7: =$C$10 -> 0.11 | F7: =C13 -> 5 | G7: =F7*E7 -> 0.55 | H7: =G7*'BANCO DE DADOS'!$V$13 -> 234.3033 | I7: =C11 -> 10 | J7: =I7*H7 -> 2343.033 | L7: 8 | M7: =$C$13 -> 5 | N7: =M7*L7 -> 40 | O7: 12.5 | P7: =IF(M7<=6,6,12) -> 6 | Q7: =VLOOKUP(O7,'BANCO DE DADOS'!$I$5:$J$14,2,'BANCO DE DADOS'!$J$5:$J$14) -> 94.07 | R7: =IF(P7>6,Q7,(Q7/2)) -> 47.035 | S7: =R7*L7 -> 376.28 | T7: =$C$11 -> 10 | U7: =T7*S7 -> 3762.8 | W7: =$C$13 -> 5 | X7: =(W7/0.15)+1 -> 34.333333 | Y7: 1.3 | Z7: =Y7*X7 -> 44.633333 | AA7: ='BANCO DE DADOS'!$M$5 -> 1.325 | AB7: =AA7*Z7 -> 59.139167 | AC7: =C11 -> 10 | AD7: =AC7*AB7 -> 591.39167 | AF7: =C11*2 -> 20 | AG7: 12.5 | AH7: =VLOOKUP(AG7,'BANCO DE DADOS'!I5:M14,5,'BANCO DE DADOS'!M5:M14) -> 7.8391667 | AI7: 1.2 | AJ7: =(AF7*AI7) -> 24 | AK7: =AJ7*AH7 -> 188.14
B8: 30x20 | C8: =0.3*0.2 -> 0.06 | E8: =$C$10 -> 0.11 | F8: 5 | G8: =F8*E8 -> 0.55 | H8: =G8*'BANCO DE DADOS'!$V$13 -> 234.3033 | I8: 0 | J8: =I8*H8 -> 0 | L8: 4 | M8: =$C$13 -> 5 | N8: =M8*L8 -> 20 | O8: 10 | P8: =IF(M8<=6,6,12) -> 6 | Q8: =VLOOKUP(O8,'BANCO DE DADOS'!$I$5:$J$14,2,'BANCO DE DADOS'!$J$5:$J$14) -> 61.76 | R8: =IF(P8>6,Q8,(Q8/2)) -> 30.88 | S8: =R8*L8 -> 123.52 | T8: =$C$11 -> 10 | U8: =T8*S8 -> 1235.2 | W8: =$C$13 -> 5 | X8: =(W8/0.15)+1 -> 34.333333 | Y8: 1.3 | Z8: =Y8*X8 -> 44.633333 | AA8: ='BANCO DE DADOS'!$M$5 -> 1.325 | AB8: =AA8*Z8 -> 59.139167 | AC8: 0 | AD8: =AC8*AB8 -> 0
E9: =$C$10 -> 0.11 | F9: 68 | G9: =F9*E9 -> 7.48 | H9: =G9*'BANCO DE DADOS'!$V$13 -> 3186.5249 | I9: 0 | J9: =I9*H9 -> 0 | L9: 8 | M9: =$C$13 -> 5 | N9: =M9*L9 -> 40 | O9: 12.5 | P9: =IF(M9<=6,6,12) -> 6 | Q9: =VLOOKUP(O9,'BANCO DE DADOS'!$I$5:$J$14,2,'BANCO DE DADOS'!$J$5:$J$14) -> 94.07 | R9: =IF(P9>6,Q9,(Q9/2)) -> 47.035 | S9: =R9*L9 -> 376.28 | T9: 0 | U9: =T9*S9 -> 0 | W9: =$C$13 -> 5 | X9: =(W9/0.15)+1 -> 34.333333 | Y9: 1.3 | Z9: =Y9*X9 -> 44.633333 | AA9: ='BANCO DE DADOS'!$M$5 -> 1.325 | AB9: =AA9*Z9 -> 59.139167 | AC9: 0 | AD9: =AC9*AB9 -> 0
B10: Qual usado | C10: =C6 -> 0.11 | L10: 4 | M10: =$C$13 -> 5 | N10: =M10*L10 -> 20 | O10: 10 | P10: =IF(M10<=6,6,12) -> 6 | Q10: =VLOOKUP(O10,'BANCO DE DADOS'!$I$5:$J$14,2,'BANCO DE DADOS'!$J$5:$J$14) -> 61.76 | R10: =IF(P10>6,Q10,(Q10/2)) -> 30.88 | S10: =R10*L10 -> 123.52 | T10: 0 | U10: =T10*S10 -> 0
B11: Número de VIGAS | C11: 10
B12: Metragem total | C12: =C11*C13 -> 50
B13: comprimento | C13: 5
B14: CUSTO TOTAL
B15: Concreto | C15: =SUM(J7:J9) -> 2343.033
B16: Aço longitudinal | C16: =SUM(U7:U10) -> 4998
B17: Estribo | C17: =SUM(AD7:AD9) -> 591.39167
B18: Pino | C18: =0*AC7 -> 0
B19: Gancho | C19: =AK7 -> 188.14
B20: Mão de obra
B22: Total | C22: =SUM(C15:C20) -> 8120.5647
B23: Por metro | C23: =C22/C12 -> 162.41129
B24: Por viga | C24: =C22/C11 -> 812.05647

Sheet LAJE
B3: 10 | C3: metragem
B4: 160 | C4: m²
B5: =B4*B3 -> 1600

Sheet PORTÃO
A1: ,
B4: Custo por m | C4: 350
B6: Lado | C6: 5
B7: Altura | C7: 5
B8: Metragem | C8: =C7*C6 -> 25
B9: Venda | C9: =C8*C4 -> 8750
B10: Qntd | C10: 2
C11: =C9*C10 -> 17500
